Workbook

Sheet Tabelle1
A1: I/O #
C2: 7 | D2: 6 | E2: 4 | F2: 23 | G2: 22 | H2: 5 | I2: 19 | J2: 8 | L2: Regular Key | P2: Fn +
B3: 10 | D3: ScrLk | E3: PrtSc | F3: Alt-R | J3: Alt-L | L3: Modifier
B4: 30 | C4: Home | E4: End | F4: Left | G4: Pause | J4: Up | L4: Multimedia | P4: F12 | Q4: KEY_SYSTEM_POWER_DOWN
B5: 24 | C5: Ins | E5: F12 | F5: Right | L5: switched Ger/Eng | P5: F4 | Q5: KEY_SYSTEM_SLEEP
B6: 29 | C6: Del | D6: Vol+ | E6: F11 | F6: Down | H6: Mute | I6: Vol- | J6: ThinkV | Q6: KEY_SYSTEM_WAKE_UP
B7: 27 | C7: ß | D7: p | E7: 0 | F7: - | G7: # | H7: ö | I7: ü | J7: ä
B8: 16 | C8: F8 | D8: o | E8: 9 | G8: . | H8: l | I8: F7
B9: 9 | C9: ´ | D9: i | E9: 8 | G9: , | H9: k | J9: F6 | P9: Down | Q9: KEY_MEDIA_PLAY_PAUSE
B10: 26 | C10: ^ | D10: q | E10: 1 | G10: y | H10: a | I10: Tab | J10: ESC | P10: Right | Q10: KEY_MEDIA_NEXT_TRACK
B11: 28 | G11: Shift-R | I11: Shift-L | P11: Left | Q11: KEY_MEDIA_PREV_TRACK
B12: 32 | C12: Ctrl-L | G12: Ctrl-R | P12: Up | Q12: KEY_MEDIA_STOP
B13: 31 | C13: F1 | D13: w | E13: 2 | G13: x | H13: s | I13: Caps | J13: <
B14: 17 | C14: F2 | D14: e | E14: 3 | G14: c | H14: d | I14: F3 | J14: F4 | P14: F9 | Q14: KEY_MEDIA_EJECT
B15: 25 | C15: 5 | D15: r | E15: 4 | F15: b | G15: v | H15: f | I15: t | J15: g
B16: 33 | C16: F9 | E16: F10 | F16: Space | G16: Enter | H16: \ | I16: BckSpc | J16: F5 | O16: free | Q16: KEY_MEDIA_RECORD
B17: 15 | C17: 6 | D17: u | E17: 7 | F17: n | G17: m | H17: j | I17: z | J17: h | O17: media | Q17: KEY_MEDIA_FAST_FORWARD
B18: 14 | C18: Pg-Up | D18: GUI/Win | E18: Pg-Dn | F18: Pg-R | G18: Pg-L | H18: Menu | O18: keys | Q18: KEY_MEDIA_REWIND
Q19: KEY_MEDIA_RANDOM_PLAY
Q20: KEY_MEDIA_PLAY_SKIP
B21: fn-overlay | Q21: KEY_MEDIA_PLAY
C22: 7 | D22: 6 | E22: 4 | F22: 23 | G22: 22 | H22: 5 | I22: 19 | J22: 8 | Q22: KEY_MEDIA_PAUSE
B23: 10 | D23: Num | E23: S-Abf
B24: 30 | C24: ScrBr+ | E24: SrcBr- | F24: |< | J24: [ ] Stop
B25: 24 | E25: F12/Hbrn | F25: >|
B26: 29 | E26: F11 | F26: > /||
B27: 27
B28: 16 | C28: F8/TP | I28: F7/Proj
B29: 9 | J29: F6
B30: 26
B31: 28
B32: 32
B33: 31 | C33: F1
B34: 17 | C34: F2/Lock | I34: F3/ScrSv | J34: F4/Sleep
B35: 25
B36: 33 | C36: F9/Eject | E36: F10 | J36: F5/Wifi
B37: 15
B38: 14 | C38: ThinkLED

Sheet Matrix
B2: Regular KeyMap
B3: Teensy I/O 7 | E3: 6 | F3: 4 | G3: 23 | H3: 22 | I3: 5 | J3: 19 | K3: 8 | M3: KeyTypes
C4: Keyboard Pin 5 | E4: 9 | F4: 13 | G4: 17 | H4: 15 | I4: 11 | J4: 7 | K4: 3
B5: 10 | C5: 32 | E5: Scroll-Lock | F5: Print-Screen | G5: Alt-Right | K5: Alt-Left | M5: Regular Key
B7: 30 | C7: 28 | D7: Home | F7: End | G7: Cursor Left | H7: Pause | K7: Cursor Up | M7: Modifier
B9: 24 | C9: 20 | D9: Insert | F9: F12 | G9: Cursor Right | M9: Multimedia
B11: 29 | C11: 16 | D11: Delete | E11: Vol-Up | F11: F11 | G11: Cursor Down | I11: Mute | J11: Vol-Down | K11: ThinkVantage | M11: switched Ger/Eng
B13: 27 | C13: 12 | D13: Ger:ß Intl:- | E13: p | F13: 0 | G13: Ger:- Intl:/ | H13: Ger:#' Intl:#~\ | I13: Ger:ö Intl:; | J13: Ger:ü Intl:[{ | K13: Ger:ä Intl:" | M13: ANSI-Key Missing in ISO
D14: MINUS | G14: SLASH | H14: BACKSLASH | I14: SEMICOLON | J14: LEFT_BRACE | K14: QUOTE
B15: 16 | C15: 8 | D15: F8 | E15: o | F15: 9 | H15: . | I15: l | J15: F7 | M15: Added in ISO Missing in ANSI
H16: PERIOD
B17: 9 | C17: 4 | D17: ´ | E17: i | F17: 8 | H17: , | I17: k | J17: }] | K17: F6 | M17: NumPad
D18: EQUAL | H18: COMMA | J18: RIGHT_BRACE
B19: 26 | C19: 22 | D19: ^ | E19: q | F19: 1 | H19: Ger:y / Intl:z | I19: a | J19: Tab | K19: Esc
D20: TILDE | H20: KEY_Z
B21: 28 | C21: 26 | H21: Shift-Right | J21: Shift-Left
M22: ignore the german swaps in green,
B23: 32 | C23: 30 | D23: Ctrl-Left | H23: Ctrl-Right | M23: even the german keyboard sends
M24: the same keycodes as a UK or
B25: 31 | C25: 18 | D25: F1 | E25: w | F25: 2 | H25: x | I25: s | J25: Caps-Locks | K25: Ger: <> | Intl:\| | M25: any other ISO keyboard.
K26: NON_US_BS | M26: The mapping is only keycaps and
B27: 17 | C27: 14 | D27: F2 | E27: e | F27: 3 | H27: c | I27: d | J27: F3 | K27: F4 | M27: the operating system
B29: 25 | C29: 10 | D29: 5 | E29: r | F29: 4 | G29: b | H29: v | I29: f | J29: t | K29: g
B31: 33 | C31: 6 | D31: F9 | F31: F10 | G31: Space | H31: Enter | I31: \ | J31: Back-Space | K31: F5
I32: BACKSLASH
B33: 15 | C33: 2 | D33: 6 | E33: u | F33: 7 | G33: n | H33: m | I33: j | J33: Ger:z Intl:y | K33: h
J34: KEY_Y
B35: 14 | C35: 24 | D35: Page-Up | E35: GUI/Win | F35: Page-Down | G35: Document-Right | H35: Document-Left | I35: Menu
G36: AC_FORWARD | H36: AC_BACK
B40: Num-Lock
B41: Teensy I/O 7 | E41: 6 | F41: 4 | G41: 23 | H41: 22 | I41: 5 | J41: 19 | K41: 8 | M41: KeyTypes
C42: Keyboard Pin 5 | E42: 9 | F42: 13 | G42: 17 | H42: 15 | I42: 11 | J42: 7 | K42: 3
B43: 10 | C43: 32 | E43: Scroll-Lock | F43: Print-Screen | G43: Alt-Right | K43: Alt-Left | M43: Regular Key
B45: 30 | C45: 28 | D45: Home | F45: End | G45: Cursor Left | H45: Pause | K45: Cursor Up | M45: Modifier
B47: 24 | C47: 20 | D47: Insert | F47: F12 | G47: Cursor Right | M47: Multimedia
B49: 29 | C49: 16 | D49: Delete | E49: Vol-Up | F49: F11 | G49: Cursor Down | I49: Mute | J49: Vol-Down | K49: ThinkVantage | M49: switched Ger/Eng
B51: 27 | C51: 12 | D51: Ger:ß Intl:- | E51: * | F51: / | G51: + | H51: Ger:#' Intl:#~\ | I51: - | J51: Ger:ü Intl:[{ | K51: Ger:ä Intl:" | M51: ANSI-Key Missing in ISO
D52: MINUS | E52: KEYPAD_ASTERIX | F52: KEYPAD_SLASH | G52: KEYPAD_PLUS | H52: BACKSLASH | I52: KEYPAD_MINUS | J52: LEFT_BRACE | K52: QUOTE
B53: 16 | C53: 8 | D53: F8 | E53: 6 | F53: 9 | H53: . | I53: 3 | J53: F7 | M53: Added in ISO Missing in ANSI
E54: KEYPAD_6 | F54: KEYPAD_9 | H54: KEYPAD_PERIOD | I54: KEYPAD_3
...

Sheet Matrix (2)
B2: Regular KeyMap
B3: Teensy I/O | E3: 8 | F3: 7 | G3: 19 | H3: 4 | I3: 6 | J3: 5 | K3: 22 | L3: 23 | N3: KeyTypes
C4: Keyboard | E4: 3 | F4: 5 | G4: 7 | H4: 13 | I4: 9 | J4: 11 | K4: 15 | L4: 17
D5: RP2040 GP 6 | F5: 5 | G5: 7 | H5: 2 | I5: 4 | J5: 3 | K5: 8 | L5: 9
B6: 32 | C6: 30 | D6: =VLOOKUP(C6,Pinout!$B:$D,3,FALSE) -> 24 | F6: Ctrl-Left | K6: Ctrl-Right | N6: Fn Key-Combo
B8: 28 | C8: 26 | D8: =VLOOKUP(C8,Pinout!$B:$D,3,FALSE) -> 20 | G8: Shift-Left | K8: Shift-Right | N8: NumPad
B10: 26 | C10: 22 | D10: =VLOOKUP(C10,Pinout!$B:$D,3,FALSE) -> 18 | E10: Esc | F10: ^ | G10: Tab | H10: 1 | I10: q | J10: a | K10: Ger:y / Intl:z | N10: Added in ISO Missing in ANSI
F11: TILDE | K11: KEY_Z
B12: 31 | C12: 18 | D12: =VLOOKUP(C12,Pinout!$B:$D,3,FALSE) -> 23 | E12: Ger: <> | Intl:\| | F12: F1 | G12: Caps-Locks | H12: 2 | I12: w | J12: s | K12: x | N12: ANSI-Key Missing in ISO
E13: NON_US_BS
B14: 17 | C14: 14 | D14: =VLOOKUP(C14,Pinout!$B:$D,3,FALSE) -> 15 | E14: F4 | F14: F2 | G14: F3 | H14: 3 | I14: e | J14: d | K14: c | N14: switched Ger/Eng
B16: 25 | C16: 10 | D16: =VLOOKUP(C16,Pinout!$B:$D,3,FALSE) -> 17 | E16: g | F16: 5 | G16: t | H16: 4 | I16: r | J16: f | K16: v | L16: b | N16: Multimedia
B18: 33 | C18: 6 | D18: =VLOOKUP(C18,Pinout!$B:$D,3,FALSE) -> 26 | E18: F5 | F18: F9 | G18: Back-Space | H18: F10 | J18: \ | K18: Enter | L18: Space | N18: Modifier
J19: BACKSLASH
B20: 15 | C20: 2 | D20: =VLOOKUP(C20,Pinout!$B:$D,3,FALSE) -> 13 | E20: h | F20: 6 | G20: Ger:z Intl:y | H20: 7 | I20: u | J20: j | K20: m | L20: n | N20: Regular Key
G21: KEY_Y
B22: 9 | C22: 4 | D22: =VLOOKUP(C22,Pinout!$B:$D,3,FALSE) -> 10 | E22: F6 | F22: ´ | G22: }] | H22: 8 | I22: i | J22: k | K22: ,
F23: EQUAL | G23: RIGHT_BRACE | K23: COMMA | N23: Ignore the german swaps in
B24: 16 | C24: 8 | D24: =VLOOKUP(C24,Pinout!$B:$D,3,FALSE) -> 14 | F24: F8 | G24: F7 | H24: 9 | I24: o | J24: l | K24: . | N24: green, every ISO-keyboard
K25: PERIOD | N25: reports the same keycodes
B26: 27 | C26: 12 | D26: =VLOOKUP(C26,Pinout!$B:$D,3,FALSE) -> 19 | E26: Ger:ä Intl:" | F26: Ger:ß Intl:- | G26: Ger:ü Intl:[{ | H26: 0 | I26: p | J26: Ger:ö Intl:; | K26: Ger:#' Intl:#~\ | L26: Ger:- Intl:/ | N26: regardless of the keycaps.
E27: QUOTE | F27: MINUS | G27: LEFT_BRACE | J27: SEMICOLON | K27: BACKSLASH | L27: SLASH | N27: That is why you need to
B28: 29 | C28: 16 | D28: =VLOOKUP(C28,Pinout!$B:$D,3,FALSE) -> 21 | E28: ThinkVantage | F28: Delete | G28: Vol-Down | H28: F11 | I28: Vol-Up | J28: Mute | L28: Cursor Down | N28: select the current keymap
N29: in your OS
B30: 24 | C30: 20 | D30: =VLOOKUP(C30,Pinout!$B:$D,3,FALSE) -> 16 | F30: Insert | H30: F12 | L30: Cursor Right
B32: 14 | C32: 24 | D32: =VLOOKUP(C32,Pinout!$B:$D,3,FALSE) -> 12 | F32: Page-Up | H32: Page-Down | I32: GUI/Win | J32: Menu | K32: Document-Left | L32: Document-Right
K33: AC_BACK | L33: AC_FORWARD
B34: 30 | C34: 28 | D34: =VLOOKUP(C34,Pinout!$B:$D,3,FALSE) -> 22 | E34: Cursor Up | F34: Home | H34: End | K34: Pause | L34: Cursor Left
B36: 10 | C36: 32 | D36: =VLOOKUP(C36,Pinout!$B:$D,3,FALSE) -> 11 | E36: Alt-Left | H36: Print-Screen | I36: Scroll-Lock | L36: Alt-Right
B45: Num-Lock
B46: Teensy I/O | E46: 8 | F46: 7 | G46: 19 | H46: 4 | I46: 6 | J46: 5 | K46: 22 | L46: 23 | N46: KeyTypes
C47: Keyboard | E47: 3 | F47: 5 | G47: 7 | H47: 13 | I47: 9 | J47: 11 | K47: 15 | L47: 17
D48: RP2040 GP 6 | F48: 5 | G48: 7 | H48: 2 | I48: 4 | J48: 3 | K48: 8 | L48: 9
B49: 32 | C49: 30 | D49: =VLOOKUP(C49,Pinout!$B:$D,3,FALSE) -> 24 | F49: Ctrl-Left | K49: Ctrl-Right | N49: Fn Key-Combo
B51: 28 | C51: 26 | D51: =VLOOKUP(C51,Pinout!$B:$D,3,FALSE) -> 20 | G51: Shift-Left | K51: Shift-Right | N51: NumPad
B53: 26 | C53: 22 | D53: =VLOOKUP(C53,Pinout!$B:$D,3,FALSE) -> 18 | E53: Esc | F53: ^ | G53: Tab | H53: 1 | I53: q | J53: a | K53: Ger:y Intl:z | N53: Added in ISO Missing in ANSI
F54: TILDE | K54: KEY_Z
B55: 31 | C55: 18 | D55: =VLOOKUP(C55,Pinout!$B:$D,3,FALSE) -> 23 | E55: Ger: <>| Intl:\| | F55: F1 | G55: Caps-Lock | H55: 2 | I55: w | J55: s | K55: x | N55: ANSI-Key Missing in ISO
E56: NON_US_BS
B57: 17 | C57: 14 | D57: =VLOOKUP(C57,Pinout!$B:$D,3,FALSE) -> 15 | E57: F4 | F57: F2 | G57: F3 | H57: 3 | I57: e | J57: d | K57: c | N57: switched Ger/Eng
...

Sheet Pinout
B1: Keyboard Connector | C1: Teensy I/O | D1: RP2040 I/O | E1: Description
B2: 1 | C2: 18 | D2: 27 | E2: Fn Hot Key
B3: 2 | C3: 15 | D3: 13 | E3: Row Output
B4: 3 | C4: 8 | D4: 6 | E4: Column Input
B5: 4 | C5: 9 | D5: 10 | E5: Row Output
B6: 5 | C6: 7 | D6: 5 | E6: Column Input
B7: 6 | C7: 33 | D7: 26 | E7: Row Output
B8: 7 | C8: 19 | D8: 7 | E8: Column Input
B9: 8 | C9: 16 | D9: 14 | E9: Row Output
B10: 9 | C10: 6 | D10: 4 | E10: Column Input
B11: 10 | C11: 25 | D11: 17 | E11: Row Output
B12: 11 | C12: 5 | D12: 3 | E12: Column Input
B13: 12 | C13: 27 | D13: 19 | E13: Row Output
... B19: 18 | C19: 31 | D19: 23 | E19: Row Output
B20: 19 | E20: Power Switch | F20: J2-2
B21: 20 | C21: 24 | D21: 16 | E21: Row Output
B22: 21 | E22: NC
B23: 22 | C23: 26 | D23: 18 | E23: Row Output
B24: 23 | E24: NC
B25: 24 | C25: 14 | D25: 12 | E25: Row Output
B26: 25 | E26: NC
B27: 26 | C27: 28 | D27: 20 | E27: Row Output
B28: 27 | E28: NC
B29: 28 | C29: 30 | D29: 22 | E29: Row Output
B30: 29 | E30: NC
B31: 30 | C31: 32 | D31: 24 | E31: Row Output
B32: 31 | E32: NC
B33: 32 | C33: 10 | D33: 11 | E33: Row Output
B34: 33 | E34: NC
B35: 34 | D35: GND | E35: GND
B36: 35 | E36: NC
B37: 36 | E37: GND
B38: 37 | C38: 1 | D38: 1 | E38: Trackpoint DTA | F38: Level Translated
B39: 38 | E39: 5V
B40: 39 | C40: 0 | D40: 0 | E40: Trackpoint CLK | F40: Level Translated
B41: 40 | E41: Trackpoint RST | F41: Hardwired Reset Curcuit
C42: 2 | F42: CAPS LOCK
C43: 3 | F43: NUM LOCK
C44: 11 | F44: Touchpad CLK
C45: 12 | F45: Touchpad DTA
...
